Workbook

Sheet Overview
A1: Tesla Model 3 Highland 2026 SOP9 - Audio Upgrade BOM v2.0 Final Asset-Integrated
A2: v2.0 finalizes the engineering reference around the verified SOP9 collector capture. 241/241 manifest-listed assets passed byte-size and SHA-256 validation. All 15 target speaker connectors have metadata and terminal faceviews. Combined target location-image coverage is 14/15: X586 and X595 are retained from the prior built-in capture because the latest Tesla endpoint returned 403; X566 remains a visual-only HTTP 403 gap. Physical connector population/fitment in the delivered vehicle remains an installation-time check. HELIX V EIGHTEEN lead architecture, supplier sourcing comparisons and Pioneer/MATCH/HELIX sub-amplifier options are preserved.
A4: Budget minimum | B4: 3000 | D4: Current lead architecture / sourcing decision
A5: Budget maximum | B5: 3500 | D5: CURRENT LEAD: HELIX V EIGHTEEN DSP (18 amplified / 20 DSP) because it can finish all 15 cabin positions without a second cabin amplifier. Preserve Audison/V TWELVE/NEXT V EIGHT routes as alternatives. Exact SOP9 connector population and interposer pinning remain a physical-install verification item. Final 15-channel full-active requires bypass/rewire of the passive L/R crossover supplied in the K200.2TES4 package.
A6: Aanbevolen BOM totaal | B6: =SUM(BOM_Recommended!N5:N15)
A7: Budgetruimte | B7: =B5-B6
A8: Aantal cabin speakers | B8: =SUM(BOM_Recommended!D5:D15)
A9: Prijspeildatum | B9: 2026-09-10
A10: USD→EUR koers | B10: 0.860404
A11: Best current DE total | B11: =B6-1290+1205.9 | C11: NL DSP scenario | D11: =B6-1290+1349
A12: Beslispunten vóór definitieve bestelling
A13: 1. Pioneer subsystem identified: TS-WX1220AH donor hardware. Reuse 2×30 cm woofers + original Class-D amp; original Pioneer enclosure is NOT used. Resolve Tesla 15.5 V vs Pioneer 15.1 V max before direct power connection.
A14: 2. SOP9 reference connector metadata/pinouts are now captured and verified in v2.0. During installation verify which PAUDIO-only positions/connectors are physically populated in this exact vehicle before repinning the PP-TES/interposer; do not cut the Tesla loom.
A15: 3. 80 mm front-door en 50 mm headliner FlexMount/custom adapters fysiek proefpassen; budget bevat een adapter/pigtail-reserve.
A16: 4. Headliner L/R: PAUDIO-only X569/X579. Use AUX 2ch from Audison DSP OUT unless the PAUDIO MCU/wire path is proven usable on this BAUDIO car.
A17: 5. Prijzen zijn momentopnamen; verzendkosten/importheffingen zijn alleen meegenomen waar expliciet bekend.
A19: Kooproute voor BOM-totaal €3.393: DSP uit Duitsland (€1.290), DRC MP CAN uit NL (€179), Highland frontkit + PP-TES uit Duitsland, overige HELIX drivers via DE/EU. Verzendkosten zijn niet in het BOM-totaal opgenomen tenzij een shop ze expliciet gratis aanbiedt.
A21: MBC v1.1 aanvulling – zie MBC_Configurator, MBC_Focal_Set, MBC_Audison_Set en MBC_Quote_Mails.
A22: v1.2 correctie: bestaande Audison BEST FIT blijft leidend. Nieuwe shopprijzen en PowerBass/Ground Zero/V EIGHTEEN zijn toegevoegd als vergelijkingsroutes; geen eerdere optie is verwijderd.
A24: SOP9 EPC EVIDENCE UPDATE - 2026-09-02
A25: Verified BAUDIO 9 | B25: Front door base woofers X568/X578, tweeters X565/X575, IP L/C/R X566/X595/X576 and rear doors X586/X591.
A26: PAUDIO-only additions | B26: Front 80mm X570/X580, parcel shelf X588/X593 and headliners X569/X579. PAUDIO uses premium woofer endpoints X567/X577 instead of BAUDIO X568/X578.
A27: Headliner correction | B27: X569/X579 are shown only on the PAUDIO option branch. The BAUDIO build must not assume ready/active OEM headliner channels; route them via auxiliary amplification unless activation/wiring is verified.
A28: Audison impact | B28: The prior 11 Audison feeds remain valid for the original grouped map; add two AUX headliner feeds from Audison DSP OUT. Auxiliary amp model/price is still TBD and is NOT included in the old €3,393 baseline.
A29: Decision discipline | B29: HELIX V EIGHTEEN remains a clean 18-channel alternative, not an automatic replacement. Focal/DLS/MUSWAY/ESX/MATCH/PowerBass comparisons remain preserved.
A31: PIONEER TS-WX1220AH DONOR SUBSYSTEM - 2026-09-05
A32: Retained hardware | B32: 2 × original Pioneer ø30 cm / 12-inch woofers + original integrated Class-D amplifier removed from one TS-WX1220AH.
A33: Not retained | B33: Original Pioneer bass-reflex enclosure is NOT used.
A34: Driver installation | B34: Both woofers mounted in a custom rigid baffle/lid at the Tesla lower extra trunk storage cavity.
A35: Amplifier installation | B35: Original Pioneer amplifier remote-mounted behind the trunk side / wheel-arch trim, approximately at the OEM Premium amplifier location.
A36: Original Pioneer system rating | B36: 2×30 cm; 1000 W RMS / 3000 W max complete donor system. Original amplifier: 600 W RMS / 1200 W max Class-D.
A37: Pioneer electrical | B37: DC 14.4 V nominal; 10.8–15.1 V allowable; 50 A max current; negative ground. Pioneer wiring example specifies a dedicated 80 A fuse.
A38: Tesla LV compatibility | B38: Tesla publishes 15.5 V low-voltage. Direct Pioneer amp connection is NOT approved until actual SOP9 voltage is measured/verified; use a high-current regulated step-down supply if required.
A39: Signal route | B39: Audison/HELIX DSP dedicated subwoofer line output → RCA → original Pioneer amplifier → two donor woofers.
A40: Acoustic limitation | B40: Do not reuse Pioneer complete-enclosure frequency response/sensitivity as predicted custom-install performance. Final response depends on custom cavity volume, sealing, baffle stiffness, leakage and cabin gain.
A42: FULL HELIX i5 / i7 COMPARISON — 2026-09-06
A43: DSP conclusion | B43: HELIX V EIGHTEEN DSP selected for comparison: 18 amplified / 20 DSP channels, 15 cabin channels used, CH16-18 spare, processed RCA OUT 1/2 to retained Pioneer amplifier.
A44: i5-priority known total | B44: ='HELIX_i5_Setup'!B29
A45: i7-priority known total | B45: ='HELIX_i7_Setup'!B29
A46: Known i7 premium | B46: ='HELIX_Comparison'!C7
...

Sheet MB_Channel_Map_v2.1
A1: MB Car Audio architecture — confirmed conversation mapping
A2: This sheet separates installer-confirmed routing from engineering assumptions. No invented per-pin channel assignment is used.
A4: Zone | B4: Primary hardware | C4: Speaker/load group | D4: Status | E4: Installer evidence | F4: DSP/amp implication | G4: SOP9 decision | H4: Open verification | I4: Source type | J4: Notes
A5: Front | B5: Audison AF M8.14 bit | C5: Everything in front / front stage | D5: CONFIRMED | E5: MB: main DSP handles everything at the front | F5: Main DSP + front amplifier | G5: KEEP | H5: Exact Focal-to-SOP9 per-channel map / crossovers | I5: Installer conversation | J5: Center ICC remains a front-stage component.
A6: Rear | B6: Audison AF M4D | C6: Rear woofers + rear midranges | D6: CONFIRMED | E6: MB: M4D intended for everything behind front seats | F6: 4-channel rear companion amp | G6: KEEP | H6: Exact grouping/passive crossover topology | I6: Installer conversation | J6: Optional rear tweeters only if desired.
A7: Rear optional | B7: Audison AF M4D | C7: Additional rear tweeters | D7: OPTIONAL | E7: MB explicitly mentioned as optional | F7: Would share/group rear architecture as engineered | G7: OPTIONAL | H7: Whether used at all; final channel/load map | I7: Installer conversation | J7: Do not consume channels without acoustic reason.
A8: Sub | B8: Audison AF M1D | C8: 2 × Pioneer TS-WX1220AH donor woofers | D8: PROVISIONAL / HIGH CONFIDENCE | E8: Conversation indicates donor woofers are retained and likely driven by one Audison amp | F8: Dedicated mono sub amp | G8: KEEP DONOR DRIVERS | H8: Measure each loose donor driver DCR/impedance and confirm series/parallel load before connection | I8: Installer conversation + engineering inference | J8: Do not reuse earlier assumed Pioneer load without measurement.
A9: Upper/headliner immersive | B9: OMIT | C9: X569 / X579 upper center/headliner music positions | D9: CONFIRMED RECOMMENDATION | E9: MB and previous installer independently advised omission for music | F9: No amplifier channels reserved | G9: OMIT FOR MUSIC | H9: None unless later cinematic/immersive experiment requested | I9: Two installer recommendations | J9: Reported OEM use is minimal for music; mainly immersive/movie context.
A10: Dashboard center | B10: Audison AF M8.14 bit + Focal ICC T3Y 100 | C10: Center stage | D10: KEEP | E10: ICC is included in actual MB hardware quote | F10: Front-stage DSP channel | G10: KEEP | H10: Final level/EQ and exact SOP9 connector | I10: Quote + installer architecture | J10: Not the same as the omitted upper/headliner immersive speakers.
A11: Tesla interface | B11: MATCH PP-TES 1.7B Highland | C11: OEM signal harness basis | D11: CONFIRMED PRODUCT / CUSTOM AUDISON USE | E11: Quoted by MB | F11: Interposer requires Audison-side engineering | G11: KEEP | H11: Pinout/repin and signal mapping | I11: Quote + manufacturer docs | J11: Manufacturer officially specifies UP10DSP use; Audison use is custom.

Sheet DSP_Tuning_Compare
A1: DSP tuning comparison — Audison vs HELIX
A2: Manufacturer capabilities are separated from MB Car Audio field experience. The earlier claim “HELIX is purely manual” is corrected: HELIX has automation, but not an equivalent fully automatic end-to-end workflow.
A4: Aspect | B4: Audison / bit Drive 3.1 + ACCORDO | C4: HELIX / DSP PC-Tool 6 | D4: Assessment | E4: Evidence type | F4: Audison source | G4: HELIX source | H4: Checked | I4: Notes
A5: Measurement microphone | B5: Supported USB measurement microphones / interfaces | C5: Supported measurement workflow | D5: Both support acoustic measurement | E5: Manufacturer | F5: https://audison.com/bit-drive-3-1/ | G5: https://www.audiotec-fischer.de/en/tools/dsp-pc-tool/download-6 | H5: 2026-09-10 | I5: Use a calibrated microphone and correct mic file where applicable.
A6: Automatic output EQ | B6: ACCORDO automatically tunes output EQ | C6: TuneEQ / TuneToTarget provide assisted/automatic EQ functions | D6: Both have EQ automation | E6: Manufacturer | F6: https://audison.zendesk.com/hc/en-gb/articles/35741332904465-bit-Drive-User-manual | G6: https://www.audiotec-fischer.de/en/tools/dsp-pc-tool/download-6 | H6: 2026-09-10 | I6: HELIX is not correctly described as “measurement only”.
A7: Automatic time alignment / delay | B7: ACCORDO calculates/tunes delays as part of automatic tune | C7: DSP PC-Tool 6 includes Automatic Time Measurement / assisted time workflow | D7: Audison more integrated in one workflow | E7: Manufacturer | F7: https://audison.zendesk.com/hc/en-gb/articles/35741332904465-bit-Drive-User-manual | G7: https://www.audiotec-fischer.de/en/tools/dsp-pc-tool/download-6 | H7: 2026-09-10 | I7: Exact final workflow still depends on system topology.
A8: Automatic output levels | B8: ACCORDO tunes output levels and system level calibration | C8: TuneToTarget includes automatic output level adjustment; final calibration still specialist-driven | D8: Both automate levels to a degree; Audison positions ACCORDO as fuller auto-tune | E8: Manufacturer | F8: https://audison.com/bit-drive-3-1/ | G8: https://www.audiotec-fischer.de/en/tools/dsp-pc-tool/download-6 | H8: 2026-09-10 | I8: Avoid “HELIX cannot auto-adjust anything”.
A9: Fully automatic claim | B9: Audison explicitly markets ACCORDO as automatic system tuning | C9: Audiotec Fischer explicitly describes TuneToTarget as partially automated, not a fully automatic tuning system | D9: Meaningful Audison workflow advantage | E9: Manufacturer | F9: https://audison.com/bit-drive-3-1/ | G9: https://www.audiotec-fischer.de/en/tools/dsp-pc-tool/download-6 | H9: 2026-09-10 | I9: HELIX still expects correct crossovers, polarity, time alignment preparation and expert final calibration.
A10: Typical installer tuning time | B10: ~3 hours average | C10: ~8 hours average | D10: ~5 h practical delta in MB experience | E10: MB Car Audio field experience | H10: 2026-09-10 | I10: Not a manufacturer benchmark or guaranteed project duration.
A11: Preset handling | B11: Each setup/preset still needs final validation | C11: Each setup/preset still needs final validation | D11: Do not assume one tune covers every listening target automatically | E11: Engineering | H11: 2026-09-10 | I11: Keep measurement evidence per final preset.

Sheet EU_Price_Matrix_v2.1
A1: EU price matrix v2.1 — NL / DE / BE / FR
A2: Snapshot 2026-09-10. “Average” = average of available lowest observed market prices (one low per country), not a statistical market-wide average. Blank market = no sufficiently reliable current indexed local offer captured. Shipping/checkout/stock remain final-order checks.
A4: Priority | B4: Product | C4: Category | D4: In MB quote | E4: Qty | F4: MB quote €/unit | G4: NL low € | H4: NL seller | I4: NL source | J4: DE low € | K4: DE seller | L4: DE source | M4: BE low € | N4: BE seller | O4: BE source | P4: FR low € | Q4: FR seller | R4: FR source | S4: Cheapest € | T4: Cheapest market | U4: Avg country-low € | V4: Country coverage | W4: Saving vs MB / unit | X4: Saving vs MB total | Y4: Checked | Z4: Confidence | AA4: Price action | AB4: Notes | AC4: Documentation / official source | AD4: Purchase relevance
A5: A | B5: Audison AF LINK | C5: Interconnect | D5: YES | E5: 1 | F5: 18.95 | G5: 18.95 | H5: MB Car Audio quote | I5: Reference_Assets/MB_Car_Audio_Proposal_2026-09-10/MB_Car_Audio_quote_cart_2026-09-10.png | K5: NO CURRENT INDEXED LOCAL OFFER FOUND | N5: NO CURRENT INDEXED LOCAL OFFER FOUND | P5: 29.9 | Q5: Multison | R5: https://multison.fr/products/audison-af-link-cable-cable-de-liaison-pour-amplificateurs-af-bit-et-af-d | S5: =IF(COUNT(G5,J5,M5,P5)=0,"",MIN(G5,J5,M5,P5)) | T5: =IF(S5="","",IF(G5=S5,"NL",IF(J5=S5,"DE",IF(M5=S5,"BE","FR")))) | U5: =IF(COUNT(G5,J5,M5,P5)=0,"",AVERAGE(G5,J5,M5,P5)) | V5: =COUNT(G5,J5,M5,P5) | W5: =IF(OR(F5="",S5=""),"",F5-S5) | X5: =IF(OR(E5="",W5=""),"",E5*W5) | Y5: 2026-09-10 | Z5: MEDIUM | AA5: KEEP MB / CONVENIENCE | AC5: https://audison.com/ | AD5: CURRENT MB QUOTE
A6: A | B6: Audison AF M1D | C6: Sub amplifier | D6: YES | E6: 1 | F6: 599 | G6: 599 | H6: MB Car Audio quote | I6: Reference_Assets/MB_Car_Audio_Proposal_2026-09-10/MB_Car_Audio_quote_cart_2026-09-10.png | J6: 595.9 | K6: Audiomativ | L6: https://www.audiomativ.de/Car-HiFi-Navigation/Endstufen/1-Kanal/ | N6: NO CURRENT INDEXED LOCAL OFFER FOUND | P6: 599 | Q6: Sebasto / Multison | R6: https://multison.fr/ | S6: =IF(COUNT(G6,J6,M6,P6)=0,"",MIN(G6,J6,M6,P6)) | T6: =IF(S6="","",IF(G6=S6,"NL",IF(J6=S6,"DE",IF(M6=S6,"BE","FR")))) | U6: =IF(COUNT(G6,J6,M6,P6)=0,"",AVERAGE(G6,J6,M6,P6)) | V6: =COUNT(G6,J6,M6,P6) | W6: =IF(OR(F6="",S6=""),"",F6-S6) | X6: =IF(OR(E6="",W6=""),"",E6*W6) | Y6: 2026-09-10 | Z6: MEDIUM | AA6: SPLIT-BUY CANDIDATE | AB6: Provisional donor-sub role; driver load verification required. | AC6: https://audison.com/product/af-m1d/ | AD6: CURRENT MB QUOTE
A7: A | B7: Audison AF M4D | C7: Amplifier | D7: YES | E7: 1 | F7: 599 | G7: 599 | H7: MB Car Audio quote | I7: Reference_Assets/MB_Car_Audio_Proposal_2026-09-10/MB_Car_Audio_quote_cart_2026-09-10.png | J7: 462.48 | K7: Audiomativ | L7: https://www.audiomativ.de/Marken-Shop/AUDISON/4-Kanal-Endstufen/ | N7: NO CURRENT INDEXED LOCAL OFFER FOUND | P7: 649 | Q7: Multison | R7: https://multison.fr/ | S7: =IF(COUNT(G7,J7,M7,P7)=0,"",MIN(G7,J7,M7,P7)) | T7: =IF(S7="","",IF(G7=S7,"NL",IF(J7=S7,"DE",IF(M7=S7,"BE","FR")))) | U7: =IF(COUNT(G7,J7,M7,P7)=0,"",AVERAGE(G7,J7,M7,P7)) | V7: =COUNT(G7,J7,M7,P7) | W7: =IF(OR(F7="",S7=""),"",F7-S7) | X7: =IF(OR(E7="",W7=""),"",E7*W7) | Y7: 2026-09-10 | Z7: MEDIUM | AA7: SPLIT-BUY CANDIDATE | AC7: https://audison.com/product/af-m4d/ | AD7: CURRENT MB QUOTE
A8: A | B8: Audison AF M8.14 bit | C8: DSP amplifier | D8: YES | E8: 1 | F8: 1199 | G8: 1199 | H8: AutoSound24 / ACR | I8: https://www.autosound24.nl/producten/AUD-DSPAMP-AF-M8-14BIT | J8: 1049 | K8: Audiomativ / Idealo | L8: https://www.idealo.de/preisvergleich/OffersOfProduct/203732550_-af-m8-14-bit-audison.html | N8: NO CURRENT INDEXED LOCAL OFFER FOUND | P8: 999 | Q8: Sebasto | R8: https://www.sebastoautoradio.net/amplificateur-8-canaux-dsp-hi-res-audison-af-m8-14bit.html | S8: =IF(COUNT(G8,J8,M8,P8)=0,"",MIN(G8,J8,M8,P8)) | T8: =IF(S8="","",IF(G8=S8,"NL",IF(J8=S8,"DE",IF(M8=S8,"BE","FR")))) | U8: =IF(COUNT(G8,J8,M8,P8)=0,"",AVERAGE(G8,J8,M8,P8)) | V8: =COUNT(G8,J8,M8,P8) | W8: =IF(OR(F8="",S8=""),"",F8-S8) | X8: =IF(OR(E8="",W8=""),"",E8*W8) | Y8: 2026-09-10 | Z8: HIGH | AA8: SPLIT-BUY CANDIDATE | AC8: https://audison.com/product/af-m8-14-bit/ | AD8: CURRENT MB QUOTE
A9: A | B9: Audison DRC AC | C9: Controller | D9: YES | E9: 1 | F9: 129 | G9: 129 | H9: MB Car Audio / CarCenterHifi | I9: https://mbcaraudio.nl/bass-controls/audison-drc-ac.html | J9: 129 | K9: Caraudio-Store / justSOUND | L9: https://www.caraudio-store.de/Pegelfernbedienung | N9: NO CURRENT INDEXED LOCAL OFFER FOUND | P9: 129 | Q9: Elettromedia EU store | R9: https://store.elettromedia.com/drc-ac/ | S9: =IF(COUNT(G9,J9,M9,P9)=0,"",MIN(G9,J9,M9,P9)) | T9: =IF(S9="","",IF(G9=S9,"NL",IF(J9=S9,"DE",IF(M9=S9,"BE","FR")))) | U9: =IF(COUNT(G9,J9,M9,P9)=0,"",AVERAGE(G9,J9,M9,P9)) | V9: =COUNT(G9,J9,M9,P9) | W9: =IF(OR(F9="",S9=""),"",F9-S9) | X9: =IF(OR(E9="",W9=""),"",E9*W9) | Y9: 2026-09-10 | Z9: HIGH | AA9: KEEP MB / CONVENIENCE | AC9: https://audison.com/fr/product/drc-ac/ | AD9: CURRENT MB QUOTE
A10: A | B10: Focal IC T3Y 100 | C10: Speaker | D10: YES | E10: 1 | F10: 319 | G10: 319 | H10: MB Car Audio | I10: https://mbcaraudio.nl/autospecifieke-pasklare-speakersets/focal-ic-t3y-100.html | J10: 219 | K10: Idealo | L10: https://www.idealo.de/preisvergleich/OffersOfProduct/204105665_-ic-t3y-100-focal.html | N10: NO CURRENT INDEXED LOCAL OFFER FOUND | P10: 229 | Q10: Sebasto / Multison | R10: https://www.sebastoautoradio.net/haut-parleurs-2-voies-coaxiaux-specifique-tesla-focal-ic-t3y-100.html | S10: =IF(COUNT(G10,J10,M10,P10)=0,"",MIN(G10,J10,M10,P10)) | T10: =IF(S10="","",IF(G10=S10,"NL",IF(J10=S10,"DE",IF(M10=S10,"BE","FR")))) | U10: =IF(COUNT(G10,J10,M10,P10)=0,"",AVERAGE(G10,J10,M10,P10)) | V10: =COUNT(G10,J10,M10,P10) | W10: =IF(OR(F10="",S10=""),"",F10-S10) | X10: =IF(OR(E10="",W10=""),"",E10*W10) | Y10: 2026-09-10 | Z10: MEDIUM | AA10: SPLIT-BUY CANDIDATE | AC10: https://www.focal.com/products/ic-t3y-100 | AD10: CURRENT MB QUOTE
A11: A | B11: Focal ICC T3Y 100 | C11: Speaker | D11: YES | E11: 1 | F11: 179 | G11: 179 | H11: MB Car Audio | I11: https://mbcaraudio.nl/autospecifieke-pasklare-speakersets/focal-icc-t3y-100.html | J11: 149 | K11: Idealo | L11: https://www.idealo.de/preisvergleich/OffersOfProduct/204855027_-inside-icc-t3y-100-focal.html | N11: NO CURRENT INDEXED LOCAL OFFER FOUND | P11: 129 | Q11: Sebasto | R11: https://www.sebastoautoradio.net/voies-centrale-specifique-tesla-focal-icc-t3y-100.html | S11: =IF(COUNT(G11,J11,M11,P11)=0,"",MIN(G11,J11,M11,P11)) | T11: =IF(S11="","",IF(G11=S11,"NL",IF(J11=S11,"DE",IF(M11=S11,"BE","FR")))) | U11: =IF(COUNT(G11,J11,M11,P11)=0,"",AVERAGE(G11,J11,M11,P11)) | V11: =COUNT(G11,J11,M11,P11) | W11: =IF(OR(F11="",S11=""),"",F11-S11) | X11: =IF(OR(E11="",W11=""),"",E11*W11) | Y11: 2026-09-10 | Z11: HIGH | AA11: SPLIT-BUY CANDIDATE | AC11: https://www.focal.com/products/icc-t3y-100 | AD11: CURRENT MB QUOTE
A12: A | B12: Focal IS T3Y 100 | C12: Speaker | D12: YES | E12: 1 | F12: 369 | G12: 369 | H12: MB Car Audio | I12: https://mbcaraudio.nl/autospecifieke-pasklare-speakersets/focal-is-t3y-100.html | J12: 289 | K12: Idealo current T3Y comparison | L12: https://www.idealo.de/preisvergleich/Liste/123511081/focal-t3y.html | N12: NO CURRENT INDEXED LOCAL OFFER FOUND | P12: 299 | Q12: Sebasto / Multison | R12: https://www.sebastoautoradio.net/kit-2-voies-specifique-tesla-focal-is-t3y-100.html | S12: =IF(COUNT(G12,J12,M12,P12)=0,"",MIN(G12,J12,M12,P12)) | T12: =IF(S12="","",IF(G12=S12,"NL",IF(J12=S12,"DE",IF(M12=S12,"BE","FR")))) | U12: =IF(COUNT(G12,J12,M12,P12)=0,"",AVERAGE(G12,J12,M12,P12)) | V12: =COUNT(G12,J12,M12,P12) | W12: =IF(OR(F12="",S12=""),"",F12-S12) | X12: =IF(OR(E12="",W12=""),"",E12*W12) | Y12: 2026-09-10 | Z12: HIGH | AA12: SPLIT-BUY CANDIDATE | AC12: https://www.focal.com/products/is-t3y-100 | AD12: CURRENT MB QUOTE
A13: A | B13: Focal IW T3Y 200 | C13: Speaker | D13: YES | E13: 1 | F13: 459 | G13: 459 | H13: MB Car Audio | I13: https://mbcaraudio.nl/autospecifieke-pasklare-speakersets/focal-iw-t3y-200.html | J13: 314.1 | K13: eBay marketplace / ACR-Hof via Idealo | L13: https://www.idealo.de/preisvergleich/OffersOfProduct/204855028_-iw-t3y-200-focal.html | N13: NO CURRENT INDEXED LOCAL OFFER FOUND | P13: 369 | Q13: Sebasto / Multison | R13: https://www.sebastoautoradio.net/woofer-20-cm-specifique-tesla-focal-iw-t3y-200.html | S13: =IF(COUNT(G13,J13,M13,P13)=0,"",MIN(G13,J13,M13,P13)) | T13: =IF(S13="","",IF(G13=S13,"NL",IF(J13=S13,"DE",IF(M13=S13,"BE","FR")))) | U13: =IF(COUNT(G13,J13,M13,P13)=0,"",AVERAGE(G13,J13,M13,P13)) | V13: =COUNT(G13,J13,M13,P13) | W13: =IF(OR(F13="",S13=""),"",F13-S13) | X13: =IF(OR(E13="",W13=""),"",E13*W13) | Y13: 2026-09-10 | Z13: MEDIUM | AA13: SPLIT-BUY CANDIDATE | AC13: https://www.focal.com/products/iw-t3y-200 | AD13: CURRENT MB QUOTE
A14: A | B14: HELIX Compose Ci3 K200.2TES4 Highland | C14: Speaker kit | D14: NO | H14: NO CURRENT INDEXED LOCAL OFFER FOUND | J14: 729 | K14: CarHifi-Store Bünde | L14: https://www.carhifi-store-buende.de/compose-ci3-k200.2tes4-tesla-model-3-highland | N14: NO CURRENT INDEXED LOCAL OFFER FOUND | Q14: NO CURRENT INDEXED LOCAL OFFER FOUND | S14: =IF(COUNT(G14,J14,M14,P14)=0,"",MIN(G14,J14,M14,P14)) | T14: =IF(S14="","",IF(G14=S14,"NL",IF(J14=S14,"DE",IF(M14=S14,"BE","FR")))) | U14: =IF(COUNT(G14,J14,M14,P14)=0,"",AVERAGE(G14,J14,M14,P14)) | V14: =COUNT(G14,J14,M14,P14) | W14: =IF(OR(F14="",S14=""),"",F14-S14) | X14: =IF(OR(E14="",W14=""),"",E14*W14) | Y14: 2026-09-10 | Z14: HIGH | AA14: COMPARE / VERIFY CHECKOUT | AC14: https://www.audiotec-fischer.de/en/helix/ | AD14: CURRENT COMPARISON
A15: A | B15: HELIX V EIGHTEEN DSP | C15: DSP amplifier | D15: NO | G15: 1799 | H15: ACR / Schut | I15: https://www.acr-helmond.nl/ | J15: 1799 | K15: CarHifi-Store Bünde | L15: https://www.carhifi-store-buende.de/endstufen/ | M15: 1799 | N15: HifiMotive dealer network | O15: https://www.caraudio.nl/artikel/helix/helix-v-eighteen-dsp-18-kanaals-versterker-met-20-kanaals-dsp-heveighteen | P15: 1799 | Q15: FR-deliverable ARS24 / Type-RSound reference | R15: https://www.ars24.com/en/helix-verstaerker-made-in-germany | S15: =IF(COUNT(G15,J15,M15,P15)=0,"",MIN(G15,J15,M15,P15)) | T15: =IF(S15="","",IF(G15=S15,"NL",IF(J15=S15,"DE",IF(M15=S15,"BE","FR")))) | U15: =IF(COUNT(G15,J15,M15,P15)=0,"",AVERAGE(G15,J15,M15,P15)) | V15: =COUNT(G15,J15,M15,P15) | W15: =IF(OR(F15="",S15=""),"",F15-S15) | X15: =IF(OR(E15="",W15=""),"",E15*W15) | Y15: 2026-09-10 | Z15: MEDIUM | AA15: COMPARE / VERIFY CHECKOUT | AB15: Full-active HELIX comparison route. | AC15: https://www.audiotec-fischer.de/en/helix/ | AD15: CURRENT COMPARISON
A16: A | B16: MATCH PP-TES 1.7B Highland | C16: Tesla harness | D16: YES | E16: 1 | F16: 139.95 | G16: 129 | H16: HifiMotive | I16: https://www.caraudio.nl/artikel/match/match-pp-tes-1-7b-highland-kabelset-voor-tesla-model-3-highland-y-juniper-met-base-audio-mapptes17bhl | J16: 129 | K16: Caraudio-Store / Bünde | L16: https://www.caraudio-store.de/Match-PP-TES-17B-Highland | N16: NO CURRENT INDEXED LOCAL OFFER FOUND | Q16: NO CURRENT INDEXED LOCAL OFFER FOUND | S16: =IF(COUNT(G16,J16,M16,P16)=0,"",MIN(G16,J16,M16,P16)) | T16: =IF(S16="","",IF(G16=S16,"NL",IF(J16=S16,"DE",IF(M16=S16,"BE","FR")))) | U16: =IF(COUNT(G16,J16,M16,P16)=0,"",AVERAGE(G16,J16,M16,P16)) | V16: =COUNT(G16,J16,M16,P16) | W16: =IF(OR(F16="",S16=""),"",F16-S16) | X16: =IF(OR(E16="",W16=""),"",E16*W16) | Y16: 2026-09-10 | Z16: HIGH | AA16: SPLIT-BUY CANDIDATE | AB16: Official PnP target is MATCH UP10DSP; Audison use requires custom integration. | AC16: https://www.audiotec-fischer.de/en/match/adaptors-harnesses/pp-tes-1-7b-highland | AD16: CURRENT MB QUOTE
A17: A | B17: Pioneer TS-WX1220AH | C17: Existing donor sub system | D17: NO | H17: NO CURRENT INDEXED LOCAL OFFER FOUND | K17: NO CURRENT INDEXED LOCAL OFFER FOUND | N17: NO CURRENT INDEXED LOCAL OFFER FOUND | Q17: NO CURRENT INDEXED LOCAL OFFER FOUND | S17: =IF(COUNT(G17,J17,M17,P17)=0,"",MIN(G17,J17,M17,P17)) | T17: =IF(S17="","",IF(G17=S17,"NL",IF(J17=S17,"DE",IF(M17=S17,"BE","FR")))) | U17: =IF(COUNT(G17,J17,M17,P17)=0,"",AVERAGE(G17,J17,M17,P17)) | V17: =COUNT(G17,J17,M17,P17) | W17: =IF(OR(F17="",S17=""),"",F17-S17) | X17: =IF(OR(E17="",W17=""),"",E17*W17) | Y17: 2026-09-10 | Z17: NO PRICE | AA17: COMPARE / VERIFY CHECKOUT | AB17: Owned donor hardware: online price is reference only, not purchase requirement. | AC17: https://pioneer-car.eu/nl/nl/ts-wx1220ah/ts-wx1220ah | AD17: CURRENT COMPARISON
A18: B | B18: Audison AF M12.14 bit | C18: DSP amplifier | D18: NO | G18: 1289 | H18: AutoSound24 | I18: https://www.autosound24.nl/producten/AUD-DSPAMP-AF-M12-14BIT | J18: 1205.9 | K18: Idealo / justSOUND | L18: https://www.idealo.de/preisvergleich/OffersOfProduct/203736270_-af-m12-14-bit-audison.html | N18: NO CURRENT INDEXED LOCAL OFFER FOUND | P18: 1290 | Q18: Elettromedia | R18: https://store.elettromedia.com/af-m12-14-bit/ | S18: =IF(COUNT(G18,J18,M18,P18)=0,"",MIN(G18,J18,M18,P18)) | T18: =IF(S18="","",IF(G18=S18,"NL",IF(J18=S18,"DE",IF(M18=S18,"BE","FR")))) | U18: =IF(COUNT(G18,J18,M18,P18)=0,"",AVERAGE(G18,J18,M18,P18)) | V18: =COUNT(G18,J18,M18,P18) | W18: =IF(OR(F18="",S18=""),"",F18-S18) | X18: =IF(OR(E18="",W18=""),"",E18*W18) | Y18: 2026-09-10 | Z18: MEDIUM | AA18: COMPARE / VERIFY CHECKOUT | AB18: Historical/alternative route retained. | AC18: https://audison.com/ | AD18: CURRENT COMPARISON
A19: B | B19: Audison DRC MP CAN | C19: Controller | D19: NO | G19: 179 | H19: MB Car Audio / ACR | I19: https://mbcaraudio.nl/bass-controls/audison-drc-mp-can.html | K19: NO CURRENT INDEXED LOCAL OFFER FOUND | N19: NO CURRENT INDEXED LOCAL OFFER FOUND | Q19: NO CURRENT INDEXED LOCAL OFFER FOUND | S19: =IF(COUNT(G19,J19,M19,P19)=0,"",MIN(G19,J19,M19,P19)) | T19: =IF(S19="","",IF(G19=S19,"NL",IF(J19=S19,"DE",IF(M19=S19,"BE","FR")))) | U19: =IF(COUNT(G19,J19,M19,P19)=0,"",AVERAGE(G19,J19,M19,P19)) | V19: =COUNT(G19,J19,M19,P19) | W19: =IF(OR(F19="",S19=""),"",F19-S19) | X19: =IF(OR(E19="",W19=""),"",E19*W19) | Y19: 2026-09-10 | Z19: HIGH | AA19: COMPARE / VERIFY CHECKOUT | AC19: https://audison.com/ | AD19: CURRENT COMPARISON
A20: B | B20: HELIX AMPLIFY 204 DIRECT | C20: Amplifier | D20: NO | G20: 239 | H20: HifiMotive | I20: https://www.caraudio.nl/assortiment/helix | J20: 239 | K20: DE marketplace / comparison | L20: https://www.idealo.de/ | N20: NO CURRENT INDEXED LOCAL OFFER FOUND | Q20: NO CURRENT INDEXED LOCAL OFFER FOUND | S20: =IF(COUNT(G20,J20,M20,P20)=0,"",MIN(G20,J20,M20,P20)) | T20: =IF(S20="","",IF(G20=S20,"NL",IF(J20=S20,"DE",IF(M20=S20,"BE","FR")))) | U20: =IF(COUNT(G20,J20,M20,P20)=0,"",AVERAGE(G20,J20,M20,P20)) | V20: =COUNT(G20,J20,M20,P20) | W20: =IF(OR(F20="",S20=""),"",F20-S20) | X20: =IF(OR(E20="",W20=""),"",E20*W20) | Y20: 2026-09-10 | Z20: MEDIUM | AA20: COMPARE / VERIFY CHECKOUT | AC20: https://www.audiotec-fischer.de/en/helix/ | AD20: CURRENT COMPARISON
A21: B | B21: HELIX AMPLIFY 206 DIRECT | C21: Amplifier | D21: NO | G21: 358.99 | H21: HifiMotive | I21: https://www.caraudio.nl/assortiment/helix | J21: 359 | K21: ARS24 | L21: https://www.ars24.com/en/6-kanal-verstaerker/auto-endstufen | N21: NO CURRENT INDEXED LOCAL OFFER FOUND | Q21: NO CURRENT INDEXED LOCAL OFFER FOUND | S21: =IF(COUNT(G21,J21,M21,P21)=0,"",MIN(G21,J21,M21,P21)) | T21: =IF(S21="","",IF(G21=S21,"NL",IF(J21=S21,"DE",IF(M21=S21,"BE","FR")))) | U21: =IF(COUNT(G21,J21,M21,P21)=0,"",AVERAGE(G21,J21,M21,P21)) | V21: =COUNT(G21,J21,M21,P21) | W21: =IF(OR(F21="",S21=""),"",F21-S21) | X21: =IF(OR(E21="",W21=""),"",E21*W21) | Y21: 2026-09-10 | Z21: HIGH | AA21: COMPARE / VERIFY CHECKOUT | AC21: https://www.audiotec-fischer.de/en/helix/ | AD21: CURRENT COMPARISON
A22: B | B22: HELIX AMPLIFY 206 DSP | C22: DSP amplifier | D22: NO | H22: NO CURRENT INDEXED LOCAL OFFER FOUND | J22: 599 | K22: ARS24 | L22: https://www.ars24.com/en/helix-amplify-206-dsp | N22: NO CURRENT INDEXED LOCAL OFFER FOUND | P22: 599 | Q22: FR-deliverable reference | R22: https://www.ars24.com/en/helix-amplify-206-dsp | S22: =IF(COUNT(G22,J22,M22,P22)=0,"",MIN(G22,J22,M22,P22)) | T22: =IF(S22="","",IF(G22=S22,"NL",IF(J22=S22,"DE",IF(M22=S22,"BE","FR")))) | U22: =IF(COUNT(G22,J22,M22,P22)=0,"",AVERAGE(G22,J22,M22,P22)) | V22: =COUNT(G22,J22,M22,P22) | W22: =IF(OR(F22="",S22=""),"",F22-S22) | X22: =IF(OR(E22="",W22=""),"",E22*W22) | Y22: 2026-09-10 | Z22: MEDIUM | AA22: COMPARE / VERIFY CHECKOUT | AC22: https://www.audiotec-fischer.de/en/helix/ | AD22: CURRENT COMPARISON
A23: B | B23: HELIX Ci3 M100FM-S3 | C23: Speaker | D23: NO | H23: NO CURRENT INDEXED LOCAL OFFER FOUND | J23: 159 | K23: CarHifi-Store Bünde | L23: https://www.carhifi-store-buende.de/helix-ci3-m100fm-s3 | N23: NO CURRENT INDEXED LOCAL OFFER FOUND | P23: 149 | Q23: Type-RSound FR-facing | R23: https://www.type-rsound.com/en/helix-ci3-m100fm-s3.html | S23: =IF(COUNT(G23,J23,M23,P23)=0,"",MIN(G23,J23,M23,P23)) | T23: =IF(S23="","",IF(G23=S23,"NL",IF(J23=S23,"DE",IF(M23=S23,"BE","FR")))) | U23: =IF(COUNT(G23,J23,M23,P23)=0,"",AVERAGE(G23,J23,M23,P23)) | V23: =COUNT(G23,J23,M23,P23) | W23: =IF(OR(F23="",S23=""),"",F23-S23) | X23: =IF(OR(E23="",W23=""),"",E23*W23) | Y23: 2026-09-10 | Z23: MEDIUM | AA23: COMPARE / VERIFY CHECKOUT | AC23: https://www.audiotec-fischer.de/en/helix/ | AD23: CURRENT COMPARISON
A24: B | B24: HELIX Ci5 M80FM-S3 | C24: Speaker | D24: NO | H24: NO CURRENT INDEXED LOCAL OFFER FOUND | J24: 199 | K24: CarHifi-Store Bünde / ARS24 | L24: https://www.carhifi-store-buende.de/helix-ci5-m80fm-s3 | N24: NO CURRENT INDEXED LOCAL OFFER FOUND | Q24: NO CURRENT INDEXED LOCAL OFFER FOUND | S24: =IF(COUNT(G24,J24,M24,P24)=0,"",MIN(G24,J24,M24,P24)) | T24: =IF(S24="","",IF(G24=S24,"NL",IF(J24=S24,"DE",IF(M24=S24,"BE","FR")))) | U24: =IF(COUNT(G24,J24,M24,P24)=0,"",AVERAGE(G24,J24,M24,P24)) | V24: =COUNT(G24,J24,M24,P24) | W24: =IF(OR(F24="",S24=""),"",F24-S24) | X24: =IF(OR(E24="",W24=""),"",E24*W24) | Y24: 2026-09-10 | Z24: HIGH | AA24: COMPARE / VERIFY CHECKOUT | AC24: https://www.audiotec-fischer.de/en/helix/ | AD24: CURRENT COMPARISON
A25: B | B25: HELIX Ci7 M100FM-S3 | C25: Speaker | D25: NO | H25: NO CURRENT INDEXED LOCAL OFFER FOUND | J25: 399 | K25: CarHifi-Store Bünde | L25: https://www.carhifi-store-buende.de/lautsprecher/helix-compose/helix-compose-i7/ | N25: NO CURRENT INDEXED LOCAL OFFER FOUND | Q25: NO CURRENT INDEXED LOCAL OFFER FOUND | S25: =IF(COUNT(G25,J25,M25,P25)=0,"",MIN(G25,J25,M25,P25)) | T25: =IF(S25="","",IF(G25=S25,"NL",IF(J25=S25,"DE",IF(M25=S25,"BE","FR")))) | U25: =IF(COUNT(G25,J25,M25,P25)=0,"",AVERAGE(G25,J25,M25,P25)) | V25: =COUNT(G25,J25,M25,P25) | W25: =IF(OR(F25="",S25=""),"",F25-S25) | X25: =IF(OR(E25="",W25=""),"",E25*W25) | Y25: 2026-09-10 | Z25: HIGH | AA25: COMPARE / VERIFY CHECKOUT | AC25: https://www.audiotec-fischer.de/en/helix/ | AD25: CURRENT COMPARISON
A26: B | B26: HELIX Ci7 T20FM-SC | C26: Tweeter | D26: NO | H26: NO CURRENT INDEXED LOCAL OFFER FOUND | J26: 399 | K26: CarHifi-Store Bünde | L26: https://www.carhifi-store-buende.de/helix-ci7-t20fm-sc | N26: NO CURRENT INDEXED LOCAL OFFER FOUND | Q26: NO CURRENT INDEXED LOCAL OFFER FOUND | S26: =IF(COUNT(G26,J26,M26,P26)=0,"",MIN(G26,J26,M26,P26)) | T26: =IF(S26="","",IF(G26=S26,"NL",IF(J26=S26,"DE",IF(M26=S26,"BE","FR")))) | U26: =IF(COUNT(G26,J26,M26,P26)=0,"",AVERAGE(G26,J26,M26,P26)) | V26: =COUNT(G26,J26,M26,P26) | W26: =IF(OR(F26="",S26=""),"",F26-S26) | X26: =IF(OR(E26="",W26=""),"",E26*W26) | Y26: 2026-09-10 | Z26: HIGH | AA26: COMPARE / VERIFY CHECKOUT | AC26: https://www.audiotec-fischer.de/en/helix/ | AD26: CURRENT COMPARISON
A27: B | B27: HELIX Ci7 W200FM-S3 | C27: Speaker | D27: NO | H27: NO CURRENT INDEXED LOCAL OFFER FOUND | J27: 509 | K27: CarHifi-Store Bünde no-grille reference | L27: https://www.carhifi-store-buende.de/lautsprecher/helix-compose/helix-compose-i7/ | N27: NO CURRENT INDEXED LOCAL OFFER FOUND | Q27: NO CURRENT INDEXED LOCAL OFFER FOUND | S27: =IF(COUNT(G27,J27,M27,P27)=0,"",MIN(G27,J27,M27,P27)) | T27: =IF(S27="","",IF(G27=S27,"NL",IF(J27=S27,"DE",IF(M27=S27,"BE","FR")))) | U27: =IF(COUNT(G27,J27,M27,P27)=0,"",AVERAGE(G27,J27,M27,P27)) | V27: =COUNT(G27,J27,M27,P27) | W27: =IF(OR(F27="",S27=""),"",F27-S27) | X27: =IF(OR(E27="",W27=""),"",E27*W27) | Y27: 2026-09-10 | Z27: HIGH | AA27: COMPARE / VERIFY CHECKOUT | AC27: https://www.audiotec-fischer.de/en/helix/ | AD27: CURRENT COMPARISON
A28: B | B28: HELIX DIRECTOR for SCP | C28: Controller | D28: NO | G28: 299 | H28: HifiMotive | I28: https://www.caraudio.nl/assortiment/helix | J28: 249 | K28: Caraudio-store / ARS24 | L28: https://www.ars24.com/en/helix-director-for-scp | N28: NO CURRENT INDEXED LOCAL OFFER FOUND | P28: 249 | Q28: ARS24 FR delivery | R28: https://www.ars24.com/en/helix-director-for-scp | S28: =IF(COUNT(G28,J28,M28,P28)=0,"",MIN(G28,J28,M28,P28)) | T28: =IF(S28="","",IF(G28=S28,"NL",IF(J28=S28,"DE",IF(M28=S28,"BE","FR")))) | U28: =IF(COUNT(G28,J28,M28,P28)=0,"",AVERAGE(G28,J28,M28,P28)) | V28: =COUNT(G28,J28,M28,P28) | W28: =IF(OR(F28="",S28=""),"",F28-S28) | X28: =IF(OR(E28="",W28=""),"",E28*W28) | Y28: 2026-09-10 | Z28: HIGH | AA28: COMPARE / VERIFY CHECKOUT | AC28: https://www.audiotec-fischer.de/en/helix/ | AD28: CURRENT COMPARISON
A29: B | B29: HELIX M ONE | C29: Sub amplifier | D29: NO | G29: 299 | H29: NL specialist reference | I29: https://www.caraudio.nl/assortiment/helix | J29: 299 | K29: CarHifi-Store Bünde | L29: https://www.carhifi-store-buende.de/endstufen/helix/ | N29: NO CURRENT INDEXED LOCAL OFFER FOUND | Q29: NO CURRENT INDEXED LOCAL OFFER FOUND | S29: =IF(COUNT(G29,J29,M29,P29)=0,"",MIN(G29,J29,M29,P29)) | T29: =IF(S29="","",IF(G29=S29,"NL",IF(J29=S29,"DE",IF(M29=S29,"BE","FR")))) | U29: =IF(COUNT(G29,J29,M29,P29)=0,"",AVERAGE(G29,J29,M29,P29)) | V29: =COUNT(G29,J29,M29,P29) | W29: =IF(OR(F29="",S29=""),"",F29-S29) | X29: =IF(OR(E29="",W29=""),"",E29*W29) | Y29: 2026-09-10 | Z29: MEDIUM | AA29: COMPARE / VERIFY CHECKOUT | AC29: https://www.audiotec-fischer.de/en/helix/ | AD29: CURRENT COMPARISON
A30: B | B30: HELIX M ONE X | C30: Sub amplifier | D30: NO | G30: 379 | H30: NL specialist reference | I30: https://www.caraudio.nl/assortiment/helix | J30: 349 | K30: DE current comparison | L30: https://www.carhifi-store-buende.de/helix-m-one-x | N30: NO CURRENT INDEXED LOCAL OFFER FOUND | Q30: NO CURRENT INDEXED LOCAL OFFER FOUND | S30: =IF(COUNT(G30,J30,M30,P30)=0,"",MIN(G30,J30,M30,P30)) | T30: =IF(S30="","",IF(G30=S30,"NL",IF(J30=S30,"DE",IF(M30=S30,"BE","FR")))) | U30: =IF(COUNT(G30,J30,M30,P30)=0,"",AVERAGE(G30,J30,M30,P30)) | V30: =COUNT(G30,J30,M30,P30) | W30: =IF(OR(F30="",S30=""),"",F30-S30) | X30: =IF(OR(E30="",W30=""),"",E30*W30) | Y30: 2026-09-10 | Z30: MEDIUM | AA30: COMPARE / VERIFY CHECKOUT | AC30: https://www.audiotec-fischer.de/en/helix/ | AD30: CURRENT COMPARISON
A31: B | B31: HELIX NEXT V EIGHT DSP ULTIMATE | C31: DSP amplifier | D31: NO | G31: 1349 | H31: ACR / Schut | I31: https://www.acr-helmond.nl/ | J31: 1349 | K31: Caraudio-Store / Audiomativ | L31: https://www.caraudio-store.de/DSP-Verstaerker | N31: NO CURRENT INDEXED LOCAL OFFER FOUND | P31: 1349 | Q31: Type-RSound FR-facing | R31: https://www.type-rsound.com/fr/categories/audio-de-voiture/amplificateur/8-canaux.html | S31: =IF(COUNT(G31,J31,M31,P31)=0,"",MIN(G31,J31,M31,P31)) | T31: =IF(S31="","",IF(G31=S31,"NL",IF(J31=S31,"DE",IF(M31=S31,"BE","FR")))) | U31: =IF(COUNT(G31,J31,M31,P31)=0,"",AVERAGE(G31,J31,M31,P31)) | V31: =COUNT(G31,J31,M31,P31) | W31: =IF(OR(F31="",S31=""),"",F31-S31) | X31: =IF(OR(E31="",W31=""),"",E31*W31) | Y31: 2026-09-10 | Z31: MEDIUM | AA31: COMPARE / VERIFY CHECKOUT | AC31: https://www.audiotec-fischer.de/en/helix/ | AD31: CURRENT COMPARISON
A32: B | B32: HELIX V TWELVE DSP MK2 | C32: DSP amplifier | D32: NO | G32: 1499 | H32: ACR Helmond / Schut | I32: https://www.acr-helmond.nl/helix-v-twelve-dsp-mk2.htm | J32: 1499 | K32: Caraudio-Store / ARS24 | L32: https://www.caraudio-store.de/Helix-V-TWELVE-DSP-MK2 | M32: 1499 | N32: HifiMotive dealer network | O32: https://www.caraudio.nl/assortiment/helix | P32: 1499 | Q32: ARS24 FR delivery | R32: https://www.ars24.com/en/helix-v-twelve-dsp-mk2 | S32: =IF(COUNT(G32,J32,M32,P32)=0,"",MIN(G32,J32,M32,P32)) | T32: =IF(S32="","",IF(G32=S32,"NL",IF(J32=S32,"DE",IF(M32=S32,"BE","FR")))) | U32: =IF(COUNT(G32,J32,M32,P32)=0,"",AVERAGE(G32,J32,M32,P32)) | V32: =COUNT(G32,J32,M32,P32) | W32: =IF(OR(F32="",S32=""),"",F32-S32) | X32: =IF(OR(E32="",W32=""),"",E32*W32) | Y32: 2026-09-10 | Z32: MEDIUM | AA32: COMPARE / VERIFY CHECKOUT | AC32: https://www.audiotec-fischer.de/en/helix/ | AD32: CURRENT COMPARISON
A33: B | B33: MATCH UP 10DSP MK2 | C33: DSP amplifier | D33: NO | G33: 1049 | H33: HifiMotive / ACR | I33: https://www.caraudio.nl/artikel/match-up-10dsp-mk2-10-kanaals-dsp-versterker-maup10dspmk2 | J33: 1049 | K33: ARS24 / DE sellers | L33: https://www.ars24.com/en/match-up10dsp-mk2 | N33: NO CURRENT INDEXED LOCAL OFFER FOUND | Q33: NO CURRENT INDEXED LOCAL OFFER FOUND | S33: =IF(COUNT(G33,J33,M33,P33)=0,"",MIN(G33,J33,M33,P33)) | T33: =IF(S33="","",IF(G33=S33,"NL",IF(J33=S33,"DE",IF(M33=S33,"BE","FR")))) | U33: =IF(COUNT(G33,J33,M33,P33)=0,"",AVERAGE(G33,J33,M33,P33)) | V33: =COUNT(G33,J33,M33,P33) | W33: =IF(OR(F33="",S33=""),"",F33-S33) | X33: =IF(OR(E33="",W33=""),"",E33*W33) | Y33: 2026-09-10 | Z33: HIGH | AA33: COMPARE / VERIFY CHECKOUT | AC33: https://www.audiotec-fischer.de/en/match/ | AD33: CURRENT COMPARISON
A34: B | B34: MATCH UP 1FX | C34: Sub amplifier | D34: NO | G34: 299 | H34: HifiMotive | I34: https://www.caraudio.nl/assortiment/match | J34: 299 | K34: ARS24 | L34: https://www.ars24.com/en/match-up1fx | N34: NO CURRENT INDEXED LOCAL OFFER FOUND | P34: 299 | Q34: ARS24 FR delivery | R34: https://www.ars24.com/en/match-up1fx | S34: =IF(COUNT(G34,J34,M34,P34)=0,"",MIN(G34,J34,M34,P34)) | T34: =IF(S34="","",IF(G34=S34,"NL",IF(J34=S34,"DE",IF(M34=S34,"BE","FR")))) | U34: =IF(COUNT(G34,J34,M34,P34)=0,"",AVERAGE(G34,J34,M34,P34)) | V34: =COUNT(G34,J34,M34,P34) | W34: =IF(OR(F34="",S34=""),"",F34-S34) | X34: =IF(OR(E34="",W34=""),"",E34*W34) | Y34: 2026-09-10 | Z34: MEDIUM | AA34: COMPARE / VERIFY CHECKOUT | AC34: https://www.audiotec-fischer.de/en/match/ | AD34: CURRENT COMPARISON
A35: C | B35: Audison AP 2 MV | C35: Speaker | D35: NO | G35: 119 | H35: MB Car Audio / AutoSound24 | I35: https://mbcaraudio.nl/87-cm-/audison-ap-2-mv.html | K35: NO CURRENT INDEXED LOCAL OFFER FOUND | N35: NO CURRENT INDEXED LOCAL OFFER FOUND | Q35: NO CURRENT INDEXED LOCAL OFFER FOUND | S35: =IF(COUNT(G35,J35,M35,P35)=0,"",MIN(G35,J35,M35,P35)) | T35: =IF(S35="","",IF(G35=S35,"NL",IF(J35=S35,"DE",IF(M35=S35,"BE","FR")))) | U35: =IF(COUNT(G35,J35,M35,P35)=0,"",AVERAGE(G35,J35,M35,P35)) | V35: =COUNT(G35,J35,M35,P35) | W35: =IF(OR(F35="",S35=""),"",F35-S35) | X35: =IF(OR(E35="",W35=""),"",E35*W35) | Y35: 2026-09-10 | Z35: HIGH | AA35: COMPARE / VERIFY CHECKOUT | AC35: https://audison.com/ | AD35: ALTERNATIVE / HISTORICAL
A36: C | B36: Audison AP TSL 8 | C36: Woofer | D36: NO | H36: NO CURRENT INDEXED LOCAL OFFER FOUND | K36: NO CURRENT INDEXED LOCAL OFFER FOUND | N36: NO CURRENT INDEXED LOCAL OFFER FOUND | Q36: NO CURRENT INDEXED LOCAL OFFER FOUND | S36: =IF(COUNT(G36,J36,M36,P36)=0,"",MIN(G36,J36,M36,P36)) | T36: =IF(S36="","",IF(G36=S36,"NL",IF(J36=S36,"DE",IF(M36=S36,"BE","FR")))) | U36: =IF(COUNT(G36,J36,M36,P36)=0,"",AVERAGE(G36,J36,M36,P36)) | V36: =COUNT(G36,J36,M36,P36) | W36: =IF(OR(F36="",S36=""),"",F36-S36) | X36: =IF(OR(E36="",W36=""),"",E36*W36) | Y36: 2026-09-10 | Z36: NO PRICE | AA36: COMPARE / VERIFY CHECKOUT | AC36: https://audison.com/ | AD36: ALTERNATIVE / HISTORICAL
A37: C | B37: Audison AP TSL M4M | C37: Speaker | D37: NO | H37: NO CURRENT INDEXED LOCAL OFFER FOUND | K37: NO CURRENT INDEXED LOCAL OFFER FOUND | N37: NO CURRENT INDEXED LOCAL OFFER FOUND | Q37: NO CURRENT INDEXED LOCAL OFFER FOUND | S37: =IF(COUNT(G37,J37,M37,P37)=0,"",MIN(G37,J37,M37,P37)) | T37: =IF(S37="","",IF(G37=S37,"NL",IF(J37=S37,"DE",IF(M37=S37,"BE","FR")))) | U37: =IF(COUNT(G37,J37,M37,P37)=0,"",AVERAGE(G37,J37,M37,P37)) | V37: =COUNT(G37,J37,M37,P37) | W37: =IF(OR(F37="",S37=""),"",F37-S37) | X37: =IF(OR(E37="",W37=""),"",E37*W37) | Y37: 2026-09-10 | Z37: NO PRICE | AA37: COMPARE / VERIFY CHECKOUT | AB37: Current Audison Tesla pack is historical comparison and not treated as Highland-compatible without confirmation. | AC37: https://audison.com/ | AD37: ALTERNATIVE / HISTORICAL
A38: C | B38: Audison AP TSL X4M | C38: Speaker | D38: NO | H38: NO CURRENT INDEXED LOCAL OFFER FOUND | K38: NO CURRENT INDEXED LOCAL OFFER FOUND | N38: NO CURRENT INDEXED LOCAL OFFER FOUND | Q38: NO CURRENT INDEXED LOCAL OFFER FOUND | S38: =IF(COUNT(G38,J38,M38,P38)=0,"",MIN(G38,J38,M38,P38)) | T38: =IF(S38="","",IF(G38=S38,"NL",IF(J38=S38,"DE",IF(M38=S38,"BE","FR")))) | U38: =IF(COUNT(G38,J38,M38,P38)=0,"",AVERAGE(G38,J38,M38,P38)) | V38: =COUNT(G38,J38,M38,P38) | W38: =IF(OR(F38="",S38=""),"",F38-S38) | X38: =IF(OR(E38="",W38=""),"",E38*W38) | Y38: 2026-09-10 | Z38: NO PRICE | AA38: COMPARE / VERIFY CHECKOUT | AC38: https://audison.com/ | AD38: ALTERNATIVE / HISTORICAL
A39: C | B39: BOXMORE BXA M50 S3.1 | C39: Speaker | D39: NO | G39: 149 | H39: HifiMotive | I39: https://www.caraudio.nl/assortiment/boxmore | K39: NO CURRENT INDEXED LOCAL OFFER FOUND | N39: NO CURRENT INDEXED LOCAL OFFER FOUND | Q39: NO CURRENT INDEXED LOCAL OFFER FOUND | S39: =IF(COUNT(G39,J39,M39,P39)=0,"",MIN(G39,J39,M39,P39)) | T39: =IF(S39="","",IF(G39=S39,"NL",IF(J39=S39,"DE",IF(M39=S39,"BE","FR")))) | U39: =IF(COUNT(G39,J39,M39,P39)=0,"",AVERAGE(G39,J39,M39,P39)) | V39: =COUNT(G39,J39,M39,P39) | W39: =IF(OR(F39="",S39=""),"",F39-S39) | X39: =IF(OR(E39="",W39=""),"",E39*W39) | Y39: 2026-09-10 | Z39: HIGH | AA39: COMPARE / VERIFY CHECKOUT | AD39: ALTERNATIVE / HISTORICAL
A40: C | B40: BOXMORE BXA M80 S3.1 | C40: Speaker | D40: NO | G40: 199 | H40: HifiMotive | I40: https://www.caraudio.nl/assortiment/boxmore | K40: NO CURRENT INDEXED LOCAL OFFER FOUND | N40: NO CURRENT INDEXED LOCAL OFFER FOUND | Q40: NO CURRENT INDEXED LOCAL OFFER FOUND | S40: =IF(COUNT(G40,J40,M40,P40)=0,"",MIN(G40,J40,M40,P40)) | T40: =IF(S40="","",IF(G40=S40,"NL",IF(J40=S40,"DE",IF(M40=S40,"BE","FR")))) | U40: =IF(COUNT(G40,J40,M40,P40)=0,"",AVERAGE(G40,J40,M40,P40)) | V40: =COUNT(G40,J40,M40,P40) | W40: =IF(OR(F40="",S40=""),"",F40-S40) | X40: =IF(OR(E40="",W40=""),"",E40*W40) | Y40: 2026-09-10 | Z40: HIGH | AA40: COMPARE / VERIFY CHECKOUT | AD40: ALTERNATIVE / HISTORICAL
A41: C | B41: BOXMORE BXS M100FL S3.1 | C41: Speaker | D41: NO | G41: 269 | H41: HifiMotive | I41: https://www.caraudio.nl/artikel/boxmore-bxs-m100fl-s3-1-100-mm-shallow-midrange-set-bxsm100fls3_1 | K41: NO CURRENT INDEXED LOCAL OFFER FOUND | N41: NO CURRENT INDEXED LOCAL OFFER FOUND | Q41: NO CURRENT INDEXED LOCAL OFFER FOUND | S41: =IF(COUNT(G41,J41,M41,P41)=0,"",MIN(G41,J41,M41,P41)) | T41: =IF(S41="","",IF(G41=S41,"NL",IF(J41=S41,"DE",IF(M41=S41,"BE","FR")))) | U41: =IF(COUNT(G41,J41,M41,P41)=0,"",AVERAGE(G41,J41,M41,P41)) | V41: =COUNT(G41,J41,M41,P41) | W41: =IF(OR(F41="",S41=""),"",F41-S41) | X41: =IF(OR(E41="",W41=""),"",E41*W41) | Y41: 2026-09-10 | Z41: HIGH | AA41: COMPARE / VERIFY CHECKOUT | AD41: ALTERNATIVE / HISTORICAL
...

Sheet MB_Quote_2026-09-10
A1: MB Car Audio — received quote evidence 2026-09-10
A2: Transcribed from the supplied cart screenshot. Hardware only; no cables, damping, mounting/consumables or labour. Installation will be performed by the owner.
A4: Line | B4: Product | C4: Qty | D4: Quoted unit € | E4: Quoted line € | F4: Role / note | G4: Evidence | H4: Quote scope | I4: Status
A5: 1 | B5: Focal IW T3Y 200 | C5: 1 | D5: 459 | E5: =C5*D5 | F5: Front woofer-set | G5: MB_Car_Audio_quote_cart_2026-09-10.png | H5: Hardware only | I5: RECEIVED
A6: 2 | B6: Focal ICC T3Y 100 | C6: 1 | D6: 179 | E6: =C6*D6 | F6: Dashboard center | G6: MB_Car_Audio_quote_cart_2026-09-10.png | H6: Hardware only | I6: RECEIVED
A7: 3 | B7: Focal IC T3Y 100 | C7: 1 | D7: 319 | E7: =C7*D7 | F7: Rear / coaxial set | G7: MB_Car_Audio_quote_cart_2026-09-10.png | H7: Hardware only | I7: RECEIVED
A8: 4 | B8: Focal IS T3Y 100 | C8: 1 | D8: 369 | E8: =C8*D8 | F8: Front mids + tweeters | G8: MB_Car_Audio_quote_cart_2026-09-10.png | H8: Hardware only | I8: RECEIVED
A9: 5 | B9: MATCH PP-TES 1.7B Highland | C9: 1 | D9: 139.95 | E9: =C9*D9 | F9: Tesla signal interposer / harness basis | G9: MB_Car_Audio_quote_cart_2026-09-10.png | H9: Hardware only | I9: RECEIVED
A10: 6 | B10: Audison AF M8.14 bit | C10: 1 | D10: 1199 | E10: =C10*D10 | F10: Alles vóór de voorstoelen / front stage DSP + amplification | G10: MB_Car_Audio_quote_cart_2026-09-10.png | H10: Hardware only | I10: RECEIVED
A11: 7 | B11: Audison AF M4D | C11: 1 | D11: 599 | E11: =C11*D11 | F11: Alles achter de voorstoelen: rear woofers, rear mids, optionele rear tweeters | G11: MB_Car_Audio_quote_cart_2026-09-10.png | H11: Hardware only | I11: RECEIVED
A12: 8 | B12: Audison AF M1D | C12: 1 | D12: 599 | E12: =C12*D12 | F12: Pioneer donor subwoofers | G12: MB_Car_Audio_quote_cart_2026-09-10.png | H12: Hardware only | I12: RECEIVED
A13: 9 | B13: Audison AF LINK | C13: 1 | D13: 18.95 | E13: =C13*D13 | F13: AF bit DSP OUT → AF D PRE IN | G13: MB_Car_Audio_quote_cart_2026-09-10.png | H13: Hardware only | I13: RECEIVED
A14: 10 | B14: Audison DRC AC | C14: 1 | D14: 129 | E14: =C14*D14 | F14: Master/sub/source/preset control | G14: MB_Car_Audio_quote_cart_2026-09-10.png | H14: Hardware only | I14: RECEIVED
C15: TOTAL | D15: =SUM(E5:E14)
A17: Scope confirmation | B17: EUR 4,010.90 is hardware only. Cabling, fusing/distribution, damping, mounting/consumable material and labour are excluded. DIY installation.

Sheet BOM_Recommended
A1: Aanbevolen BOM – 15 cabin speakers
A2: Recommended cabin baseline retained. Existing Pioneer TS-WX1220AH donor subsystem is now explicitly documented outside the cabin-speaker count; original enclosure is not used. Pioneer LV compatibility remains an open power-design gate.
A4: ID | B4: Categorie | C4: Aantal sets | D4: Speakers in set | E4: Tesla locatie / functie | F4: Merk / model | G4: Impedantie | H4: RMS / spec | I4: Fitment / adapter | J4: Aansturing | K4: Regio koopadvies | L4: Eenheidsprijs EUR | M4: Prijsstatus | N4: Regeltotaal EUR | O4: Bron / URL | P4: Opmerking
A5: DSP-01 | B5: DSP/versterker | C5: 1 | D5: 0 | E5: Cabin amplification / processing | F5: Audison Forza AF M12.14 bit | G5: 2–4 Ω | H5: 12×60 W @4Ω; 12×90 W @2Ω; 14ch DSP | I5: Universeel; custom Tesla T-harness | J5: 11 cabin amp-kanalen + DSP OUT naar Pioneer | K5: DE/NL | L5: 1290 | M5: Verified current | N5: =C5*L5 | O5: 12 versterkte kanalen; 6 DSP OUT kanalen; 1 kanaal reserve in voorgestelde map.
A6: CTRL-01 | B6: Displaycontroller | C6: 1 | D6: 0 | E6: Bestuurdersbediening | F6: Audison DRC MP CAN | G6: n.v.t. | H6: OLED; 6 DSP memories; master/sub volume | I6: DRCC aansluiting op Forza | J6: DSP control | K6: NL | L6: 179 | M6: Verified current | N6: =C6*L6 | O6: Officieel geschikt voor AF M12.14 bit.
A7: HAR-01 | B7: Tesla T-harness | C7: 1 | D7: 0 | E7: OEM 16-pin Tesla interposer | F7: MATCH PP-TES 1.7B Highland | G7: n.v.t. | H7: Tesla 16-pin plug/socket + Molex breakout | I7: Direct passend aan Tesla; Audison-zijde repinnen | J7: Signal in/out interposer | K7: DE/NL | L7: 129 | M7: Verified current | N7: =C7*L7 | O7: Fabrikant bedoelt hem voor MATCH UP10; in deze BOM alleen donor/no-cut interposer. Niet direct PnP naar Audison.
A8: SPK-01 | B8: Front speakerkit | C8: 1 | D8: 7 | E8: Front doors + dash L/C/R | F8: HELIX Compose Ci3 K200.2TES4 Highland | G8: 3 Ω | H8: 2×W200 + 2×M100 + 2×T20 + 1×C100 | I8: Highland FlexMount + connector kits inbegrepen | J8: 5 amp-kanalen door passieve L/R mid+tweeter XO | K8: DE | L8: 729 | M8: Verified current | N8: =C8*L8 | O8: Exact Highland kit; geïntegreerde 6 dB crossover voor HT/MT.
A9: SPK-02 | B9: Premium front mids | C9: 1 | D9: 2 | E9: Front doors 80 mm L/R | F9: HELIX Ci5 M80FM-S3 | G9: 3 Ω | H9: 80 mm; advanced midrange | I9: Custom/FlexMount80 Tesla adapter vereist | J9: 2 Audison kanalen L/R | K9: DE/FR | L9: 199 | M9: Verified current | N9: =C9*L9 | O9: Fysieke Highland 80mm adapter nog verifiëren.
A10: SPK-03 | B10: Headliner | C10: 1 | D10: 2 | E10: Headliner L/R | F10: HELIX Ci5 M50FM-S3 | G10: 3 Ω | H10: 50 mm full-range | I10: Custom 60→50 mm adapter/pigtail | J10: AUX 2ch amplifier via Audison DSP OUT | K10: DE/FR | L10: 169 | M10: Verified current | N10: =C10*L10 | O10: Bewust op OEM-kanalen om nieuw DSP-kanaalbudget vrij te houden. | P10: SOP9 correction retained: X569/X579 are PAUDIO-only. Use AUX 2ch from DSP OUT unless PAUDIO output/wiring is proven.
A11: SPK-04 | B11: Rear doors | C11: 1 | D11: 2 | E11: Rear doors L/R | F11: HELIX Ci3 M100FM-S3 | G11: 3 Ω | H11: 100 mm; 80 W RMS | I11: Tesla adapter/pigtail vereist | J11: 2 Audison kanalen L/R | K11: DE/EU | L11: 149 | M11: Verified current | N11: =C11*L11 | O11: Pair price.
A12: SPK-05 | B12: Parcel shelf | C12: 1 | D12: 2 | E12: Parcel shelf L/R (Premium posities) | F12: HELIX Ci3 M100FM-S3 | G12: 3 Ω | H12: 100 mm; 80 W RMS | I12: Custom Tesla mount/pigtail vereist | J12: 2 Audison kanalen L/R | K12: DE/EU | L12: 149 | M12: Verified current | N12: =C12*L12 | O12: Pair price; Premium-posities moeten mogelijk fysiek worden voorbereid.
A13: PWR-01 | B13: Voeding | C13: 1 | D13: 0 | E13: DSP amp power | F13: 16 mm² OFC + MIDI fuse 60 A + terminals | G13: n.v.t. | H13: Budget allowance | I13: Dedicated fused feed | J13: Power | K13: EU | L13: 160 | M13: Budget allowance | N13: =C13*L13 | O13: Definitieve lengte/fusepositie na installatieroute bepalen; bestaande Pioneer voeding apart laten.
A14: ADP-01 | B14: Adapters/pigtails | C14: 1 | D14: 0 | E14: 80mm/headliner/rear/parcel | F14: FlexMount/custom 3D adapters + OEM pigtails | G14: n.v.t. | H14: Budget allowance | I14: No-cut vehicle side | J14: Mechanical / wiring | K14: EU | L14: 180 | M14: Budget allowance | N14: =C14*L14 | O14: Reserve voor 80mm, 60→50mm, rear/parcel mounts en connectoren.
A15: CAB-01 | B15: Bekabeling | C15: 1 | D15: 0 | E15: Speaker/DSP/remote finishing | F15: OFC speaker cable + ferrules + braid + heatshrink | G15: n.v.t. | H15: Budget allowance | I15: Install material | J15: Signal / speaker | K15: EU | L15: 60 | M15: Budget allowance | N15: =C15*L15 | O15: Geen subwooferkabel/amp inbegrepen; bestaande Pioneer module hergebruiken.
A16: AUX-01 | B16: Auxiliary amplifier | C16: 1 | D16: 0 | E16: Headliner L/R amplification | F16: 2-channel compact amplifier - MODEL TBD | G16: TBD | H16: Suitable for 2x headliner full-range | I16: Universal; powered/fused install | J16: 2 channels from Audison DSP OUT | K16: NL/DE/BE/FR first | M16: REQUIRED - UNPRICED | O16: TBD after EU research | P16: Required by SOP9 evidence; excluded from numeric total until model/price is researched.
A17: SUB-01 | B17: Existing subwoofer donor subsystem | C17: 1 | D17: 0 | E17: Tesla lower extra trunk storage / custom baffle | F17: Pioneer TS-WX1220AH donor: 2× original 30 cm woofers | G17: Donor hardware | H17: Original system: 1000 W RMS / 3000 W max | I17: Original Pioneer enclosure NOT used | J17: Driven by retained Pioneer Class-D amp | K17: Existing / reused | L17: 0 | M17: EXISTING - RETAINED | N17: =C17*L17 | O17: https://pioneer-car.eu/ts-wx1220ah/ts-wx1220ah | P17: Two original drivers removed from TS-WX1220AH and installed in custom lower-trunk baffle/lid. Excluded from 15 cabin-speaker count.
A18: SUB-02 | B18: Existing subwoofer amplifier | C18: 1 | D18: 0 | E18: Behind trunk side / wheel-arch trim near OEM Premium amp area | F18: Original TS-WX1220AH Class-D amplifier | G18: 10.8–15.1 V supply | H18: 600 W RMS / 1200 W max; max current 50 A | I18: Remote-mounted; original enclosure NOT used | J18: DSP sub line/RCA → Pioneer amp → two donor woofers | K18: Existing / reused | L18: 0 | M18: EXISTING - RETAINED | N18: =C18*L18 | O18: https://pioneer-car.eu/asset/installation_manuals/UPLOAD_ID_28783/bb886d2a0df764bbfca7a2d7de1562b67e31f364/ | P18: Pioneer specifies negative ground; wiring example uses dedicated 80 A fuse.
A19: PWR-02 | B19: Subwoofer power compatibility gate | C19: 1 | D19: 0 | E19: Tesla LV → Pioneer donor amplifier | F19: High-current regulated DC-DC step-down - MODEL TBD IF REQUIRED | G19: Tesla 15.5 V vs Pioneer max 15.1 V | H19: Must support Pioneer specified max current 50 A; engineering margin TBD | I19: Dedicated fused branch; thermal/grounding design TBD | J19: Voltage verification / regulation | K19: NL/DE/BE/FR first | M19: BLOCKER - UNPRICED | O19: https://www.tesla.com/ownersmanual/model3/nl_nl/GUID-E414862C-CFA1-4A0B-9548-BE21C32CAA58.html | P19: DIRECT CONNECTION NOT APPROVED until actual SOP9 LV is verified. Use regulated step-down if the Pioneer amp can see >15.1 V.
M20: TOTAAL | N20: =SUM(N5:N19)
M21: Budget max | N21: =Overview!B5
M22: Headroom | N22: =N21-N20
M23: Cabin speakers | N23: =SUM(D5:D19)
A25: v2.1 NOTE
A26: Historical/comparison content retained. Current received MB proposal is authoritative in MB_Quote_2026-09-10 / MBC_Shopping_List and MB_Channel_Map_v2.1.

Sheet Price_Comparison
A1: Prijsvergelijking per regio
A2: Webprijzen opnieuw gecontroleerd op 2026-09-02. Bestaande niet-herbevestigde vergelijkprijzen blijven zichtbaar maar moeten bij checkout opnieuw worden geverifieerd.
A4: Product | B4: Market | C4: Seller | D4: Currency | E4: Listed price | F4: Qty/MOQ | G4: VAT in listed? | H4: FX to EUR | I4: EUR ex extra VAT | J4: Indicative NL VAT 21% | K4: Indicative EUR incl. NL VAT | L4: Shipping/duty | M4: Availability / confidence | N4: Source URL | O4: Checked
A5: Audison AF M12.14 bit | B5: NL | C5: MB Car Audio / AutoSound24 | D5: EUR | E5: 1349 | F5: 1 | G5: Yes | H5: 1 | I5: =E5*H5 | J5: =IF(G5="Yes",0,I5*21%) | K5: =I5+J5 | L5: Shipping varies | M5: Reverified 2026-09-02; NL stock shown | N5: https://mbcaraudio.nl/car-audio-producten/versterkers/versterkers-met-dsp | O5: 2026-09-02
A6: Audison AF M12.14 bit | B6: DE | C6: justSOUND | D6: EUR | E6: 1290 | F6: 1 | G6: Yes | H6: 1 | I6: =E6*H6 | J6: =IF(G6="Yes",0,I6*21%) | K6: =I6+J6 | L6: DE shipping stated | M6: Current / in stock | N6: https://just-sound.de/Audison-Forza-AF-M1214-bit-12-Kanal-Verstaerker-mit-DSP-180W | O6: 2026-09-01
A7: Audison AF M12.14 bit | B7: DE | C7: Idealo / just-sound.de | D7: EUR | E7: 1205.9 | F7: 1 | G7: Yes | H7: 1 | I7: =E7*H7 | J7: =IF(G7="Yes",0,I7*21%) | K7: =I7+J7 | L7: DE shipping included per Idealo; NL shipping must be verified | M7: Current comparison price; verify checkout before ordering | N7: https://www.idealo.de/preisvergleich/OffersOfProduct/203736270_-af-m12-14-bit-audison.html | O7: 2026-09-01
A8: Audison AF M12.14 bit | B8: FR/EU | C8: Elettromedia store | D8: EUR | E8: 1290 | F8: 1 | G8: Yes | H8: 1 | I8: =E8*H8 | J8: =IF(G8="Yes",0,I8*21%) | K8: =I8+J8 | L8: EU shipping | M8: Current official store | N8: https://store.elettromedia.com/af-m12-14-bit/ | O8: 2026-09-01
A9: MATCH UP 10DSP MK2 (alternative) | B9: NL | C9: HifiMotive | D9: EUR | E9: 1049 | F9: 1 | G9: Yes | H9: 1 | I9: =E9*H9 | J9: =IF(G9="Yes",0,I9*21%) | K9: =I9+J9 | L9: NL | M9: Reverified 2026-09-02; NL retail/MSRP | N9: https://www.caraudio.nl/artikel/match-up-10dsp-mk2-10-kanaals-dsp-versterker-maup10dspmk2 | O9: 2026-09-02
A10: MATCH UP 10DSP MK2 (alternative) | B10: DE/FR | C10: ARS24 | D10: EUR | E10: 1049 | F10: 1 | G10: Yes | H10: 1 | I10: =E10*H10 | J10: =IF(G10="Yes",0,I10*21%) | K10: =I10+J10 | L10: Ships DE/AT/FR | M10: Current / in stock | N10: https://www.ars24.com/en/match-up10dsp-mk2 | O10: 2026-09-01
A11: MATCH UP 10DSP MK2 (alternative) | B11: USA | C11: Crutchfield | D11: USD | E11: 1450 | F11: 1 | G11: No | H11: 0.860404 | I11: =E11*H11 | J11: =IF(G11="Yes",0,I11*21%) | K11: =I11+J11 | L11: Excl. import/shipping | M11: Current US retail | N11: https://www.crutchfield.com/shopsearch/MATCH_UP_10_DSP.html | O11: 2026-09-01
A12: Audison DRC MP CAN | B12: NL | C12: MB Car Audio | D12: EUR | E12: 179 | F12: 1 | G12: Yes | H12: 1 | I12: =E12*H12 | J12: =IF(G12="Yes",0,I12*21%) | K12: =I12+J12 | L12: Free NL shipping threshold met | M12: Reverified 2026-09-02; MBC route retained | N12: https://mbcaraudio.nl/bass-controls/audison-drc-mp-can.html | O12: 2026-09-02
A13: HELIX DIRECTOR SCP (alternative) | B13: NL | C13: HifiMotive | D13: EUR | E13: 299 | F13: 1 | G13: Yes | H13: 1 | I13: =E13*H13 | J13: =IF(G13="Yes",0,I13*21%) | K13: =I13+J13 | L13: NL | M13: Current | N13: https://www.caraudio.nl/artikel/helix-director-remote-control-met-touchscreen-en-scp-aansluiting-hedirectscp | O13: 2026-09-01
A14: MATCH PP-TES 1.7B Highland | B14: NL | C14: HifiMotive | D14: EUR | E14: 129 | F14: 1 | G14: Yes | H14: 1 | I14: =E14*H14 | J14: =IF(G14="Yes",0,I14*21%) | K14: =I14+J14 | L14: NL | M14: Reverified 2026-09-02 official NL MSRP; MBC lists €139.95 | N14: https://www.caraudio.nl/artikel/match/match-pp-tes-1-7b-highland-kabelset-voor-tesla-model-3-highland-y-juniper-met-base-audio-mapptes17bhl | O14: 2026-09-02
A15: MATCH PP-TES 1.7B Highland | B15: DE | C15: CarHifi-Store Bünde | D15: EUR | E15: 129 | F15: 1 | G15: Yes | H15: 1 | I15: =E15*H15 | J15: =IF(G15="Yes",0,I15*21%) | K15: =I15+J15 | L15: DE/EU shipping | M15: Current / in stock | N15: https://www.carhifi-store-buende.de/endstufen/ | O15: 2026-09-01
A16: HELIX Ci3 K200.2TES4 Highland | B16: DE | C16: CarHifi-Store Bünde | D16: EUR | E16: 729 | F16: 1 | G16: Yes | H16: 1 | I16: =E16*H16 | J16: =IF(G16="Yes",0,I16*21%) | K16: =I16+J16 | L16: EU shipping extra | M16: Reverified 2026-09-02; Highland-specific kit in stock | N16: https://www.carhifi-store-buende.de/compose-ci3-k200.2tes4-tesla-model-3-highland | O16: 2026-09-02
... A30: PowerBass OE40CN-T3Y | B30: GR | C30: iCan Greece | D30: EUR | E30: 121.5 | F30: 1 | G30: Yes | H30: 1 | I30: =E30*H30 | J30: =IF(G30="Yes",0,I30*21%) | K30: =I30+J30 | L30: GR/EU route TBD | M30: Current listing; use only after marketplace/shop check | N30: https://ican.gr/ήχος-και-εικόνα-αυτοκινήτου/ηχεία-αυτοκινήτου/ηχεία-εργοστασιακού-τύπου-oem/powerbass-oe40cn-t3y-διαιρούμενα-ηχεία-αυτοκινήτου-4-oem | O30: 2026-09-02
A32: FULL HELIX 2026-09-06
A33: HELIX i5-priority + V EIGHTEEN | B33: ='HELIX_i5_Setup'!B29 | C33: 15 full-active cabin channels; known hardware only
A34: HELIX i7-priority + V EIGHTEEN | B34: ='HELIX_i7_Setup'!B29 | C34: 15 full-active cabin channels; known hardware only
A35: Known i7 premium vs i5 | B35: ='HELIX_Comparison'!C7 | C35: Does not include TBD install/integration differences
A36: MATCH UP 1FX | B36: NL | C36: HifiMotive / dealer network | D36: EUR | E36: 299 | F36: 1 | G36: Yes | H36: 1 | I36: =E36*H36 | J36: =IF(G36="Yes",0,I36*21%) | K36: =I36+J36 | L36: NL dealer | M36: Current RRP; 10.5–18 V, 1 Ω stable | N36: https://www.caraudio.nl/artikel/helix-src-subwoofer-remote-control-voor-helix-versterkers-hesrc | O36: 2026-09-10
A37: MATCH UP 1FX | B37: DE/FR | C37: ARS24 | D37: EUR | E37: 299 | F37: 1 | G37: Yes | H37: 1 | I37: =E37*H37 | J37: =IF(G37="Yes",0,I37*21%) | K37: =I37+J37 | L37: Free shipping shown; HELIX/MATCH shipping only DE/AT/FR | M37: Ready for dispatch; 1–2 days | N37: https://www.ars24.com/en/match-up1fx | O37: 2026-09-10
A38: HELIX M ONE | B38: DE | C38: CarHifi-Store Bünde | D38: EUR | E38: 299 | F38: 1 | G38: Yes | H38: 1 | I38: =E38*H38 | J38: =IF(G38="Yes",0,I38*21%) | K38: =I38+J38 | L38: DE/EU shipping verify | M38: Available in 4 days listing; 10.5–16 V, 1 Ω stable | N38: https://www.carhifi-store-buende.de/endstufen/helix/ | O38: 2026-09-10
